<mujoco model="robotiq_gripper_85_tactile_model">
    <compiler angle="radian"></compiler>
    <asset>
        <mesh name="robotiq_arg2f_base_link" file="meshes/robotiq_85_gripper_tactile/robotiq_arg2f_base_link.stl" />
        <mesh name="robotiq_arg2f_85_outer_knuckle" file="meshes/robotiq_85_gripper_tactile/robotiq_arg2f_85_outer_knuckle.stl" scale="0.001 0.001 0.001" />
        <mesh name="robotiq_arg2f_85_outer_finger" file="meshes/robotiq_85_gripper_tactile/robotiq_arg2f_85_outer_finger.stl" scale="0.001 0.001 0.001" />
        <mesh name="robotiq_arg2f_85_inner_finger" file="meshes/robotiq_85_gripper_tactile/robotiq_arg2f_85_inner_finger.stl" scale="0.001 0.001 0.001" />
        <mesh name="robotiq_arg2f_85_inner_knuckle" file="meshes/robotiq_85_gripper_tactile/robotiq_arg2f_85_inner_knuckle.stl" scale="0.001 0.001 0.001" />
        <!-- <mesh name="robotiq_arg2f_base_link" file="meshes/robotiq_85_gripper_tactile/robotiq_arg2f_base_link_vis.stl" /> -->
        <mesh name="robotiq_arg2f_85_outer_knuckle_vis" file="meshes/robotiq_85_gripper_tactile/robotiq_arg2f_85_outer_knuckle_vis.stl" scale="0.001 0.001 0.001" />
        <mesh name="robotiq_arg2f_85_outer_finger_vis" file="meshes/robotiq_85_gripper_tactile/robotiq_arg2f_85_outer_finger_vis.stl" scale="0.001 0.001 0.001" />
        <mesh name="robotiq_arg2f_85_inner_finger_vis" file="meshes/robotiq_85_gripper_tactile/robotiq_arg2f_85_inner_finger_vis.stl" scale="0.001 0.001 0.001" />
        <mesh name="robotiq_arg2f_85_inner_knuckle_vis" file="meshes/robotiq_85_gripper_tactile/robotiq_arg2f_85_inner_knuckle_vis.stl" scale="0.001 0.001 0.001" />
        
        <!-- tactile -->
        <mesh name="digit_adapter"  file="meshes/robotiq_85_gripper_tactile/digit_adapter.STL"        scale="0.001 0.001 0.001"/>
        <mesh name="digit_back"     file="meshes/robotiq_85_gripper_tactile/digit_back.STL"           scale="0.001 0.001 0.001"/>
        <mesh name="digit_glass"    file="meshes/robotiq_85_gripper_tactile/digit_glass.STL"          scale="0.001 0.001 0.003"/>
        <mesh name="digit_gel"    file="meshes/robotiq_85_gripper_tactile/digit_glass.STL"          scale="0.001 0.001 0.0009"/>
        <mesh name="digit_gel_cover"      file="meshes/robotiq_85_gripper_tactile/digit_gel.STL"            scale="0.0012 0.0011 0.001"/>
        <mesh name="digit_curve"    file="meshes/robotiq_85_gripper_tactile/digit_curve_0_5.STL"  scale=".001 .001 .001"/>

        <material name="black_resin" rgba="0.1 0.1 0.1 1"/>
        <material name="silver" specular="1" shininess="0.5" reflectance="1" emission="0.25" rgba="0.82 0.82 0.82 1"/>
        <material name="transparent_glass" rgba="0.9 0.95 1 0.7"/>
    </asset>

    <tendon>
		<!--finger2 tendons-->
        <fixed name="finger2_12_cpl" range="-1 1" stiffness="0.4" springlength="0.001" limited="true">
			<joint joint="finger_joint"  coef="1"/>
			<joint joint="left_inner_finger_joint"  coef="-3"/>
			<joint joint="left_inner_knuckle_joint"  coef="1"/>
		</fixed>

		<!--Finger1 tendons-->
        <fixed name="finger1_12_cpl" range="-1 1" stiffness="0.4" springlength="0.001" limited="true">
			<joint joint="right_outer_knuckle_joint"  coef="1"/>
			<joint joint="right_inner_finger_joint"  coef="-3"/>
			<joint joint="right_inner_knuckle_joint"  coef="1"/>
		</fixed>
	</tendon>

    <actuator>
        <position name='finger_1' ctrllimited="true" kp="20" joint='finger_joint' ctrlrange='0 0.8'/>
        <position name='finger_2' ctrllimited="true" kp="20" joint='right_outer_knuckle_joint' ctrlrange='0 0.8'/>
    </actuator>

    <!-- <include file="shared.xml"></include> -->

    <worldbody>
        <body name="robotiq_85_adapter_link" pos="0.0 0 0" >
            <site name="ft_frame" pos="0 0 0" size="0.01 0.01 0.01" rgba="1 0 0 1" type="sphere" group="1" />
            <!-- This site was added for visualization. -->
            <body name="eef" pos="0 0 0.145" quat="0.707105 0 0 -0.707105">
                <site name="grip_site" pos="0 0 0" size="0.01 0.01 0.01" rgba="1 0 0 0.5" type="sphere" group="1"/>
                <site name="ee_x" pos="0.1 0 0" size="0.005 .1"  quat="0.707105  0 0.707108 0 " rgba="1 0 0 0" type="cylinder" group="1"/>
                <site name="ee_y" pos="0 0.1 0" size="0.005 .1" quat="0.707105 0.707108 0 0" rgba="0 1 0 0" type="cylinder" group="1"/>
                <site name="ee_z" pos="0 0 0.1" size="0.005 .1" quat="1 0 0 0" rgba="0 0 1 0" type="cylinder" group="1"/>
                <!-- This site was added for visualization. -->
                <site name="grip_site_cylinder" pos="0 0 0" size="0.005 10" rgba="0 1 0 0.3" type="cylinder"/>
            </body>
            <inertial pos="0 0 0" mass="0.01" diaginertia="0.001 0.001 0.001" />
            <geom type="mesh" contype="0" conaffinity="0" group="1" rgba="0.1 0.1 0.1 1" name="hand_visual" mesh="robotiq_arg2f_base_link" />
            <geom type="mesh" group="0" rgba="0.1 0.1 0.1 1" mesh="robotiq_arg2f_base_link" name="hand_collision" />
            <body name="left_outer_knuckle" pos="0 -0.0306011 0.054904" quat="0 0 0 1">
                <inertial pos="0.000163875 0.0554825 -0.0100755" quat="0.920541 0.390623 -0.00362953 0.00231744" mass="0.0311462" diaginertia="5.11372e-05 4.89464e-05 4.95906e-06" />
                <joint name="finger_joint" pos="0 0 0" axis="1 0 0" limited="true" range="0 0.8" />
                <geom type="mesh" contype="0" conaffinity="0" group="1" rgba="0.792157 0.819608 0.933333 1" name="left_outer_knuckle_visual" mesh="robotiq_arg2f_85_outer_knuckle_vis" />
                <geom type="mesh" group="0" rgba="0.792157 0.819608 0.933333 1" mesh="robotiq_arg2f_85_outer_knuckle" name="left_outer_knuckle_collision" solref="0.01 0.25" />
                <geom pos="0 0.0315 -0.0041" type="mesh" contype="0" conaffinity="0" group="1" rgba="0.1 0.1 0.1 1" name="left_outer_finger_visual" mesh="robotiq_arg2f_85_outer_finger_vis" />
                <geom pos="0 0.0315 -0.0041" type="mesh" group="0" rgba="0.1 0.1 0.1 1" mesh="robotiq_arg2f_85_outer_finger" name="left_outer_finger_collision" solref="0.01 0.25" />
                <body name="left_inner_finger" pos="0 0.0376 0.043">
                    <inertial pos="0.000199506 0.0032692 0.00175282" quat="0.933621 0.35825 -0.00273441 0.00104851" mass="0.0156391" diaginertia="1.57977e-05 1.51089e-05 1.4647e-06" />
                    <joint name="left_inner_finger_joint" pos="0 0 0" axis="1 0 0" limited="true" range="-0.8757 0.8757" />
                    <geom type="mesh" contype="0" conaffinity="0" group="1" rgba="0.1 0.1 0.1 1" name="left_inner_finger_visual" mesh="robotiq_arg2f_85_inner_finger_vis" />
                    <geom type="mesh" group="0" rgba="0.1 0.1 0.1 1" mesh="robotiq_arg2f_85_inner_finger" name="left_inner_finger_collision" solref="0.01 0.25" />
                    <geom size="0.011 0.003175 0.01875" pos="0 -0.0220203 0.03242" type="box" contype="0" conaffinity="0" group="1" rgba="0.9 0.9 0.9 1" name="left_fingertip_visual" />
                    <geom size="0.011 0.003175 0.01875" pos="0 -0.0220203 0.03242" type="box" group="0" rgba="0.9 0.9 0.9 1" name="left_fingertip_collision" solref="0.01 0.25" />
                    <geom size="0.010 0.001 0.01675" pos="0 -0.0245203 0.03242" type="box" group="0" name="left_fingerpad_collision" />
                    <!-- tactile -->
                    <body name="digit_0" pos="-0.0025 0.01 0.08" euler="1.5708 0 -1.5708"> 
                    <!-- 左右 前后 上下 -->
                        <!-- <include file="digit0_sensor.xml"></include> -->
                        <body name="digit0_sensor" pos="0 0 0" euler="0 0 0">
                            <site name="digit0_site" pos="0.012 0 0.035" rgba="1 0 0 .0" size="0.02 0.02 0.02" group="1"/>
                            <!-- <joint name="digit_joint" type="hinge" damping="0.01"></joint> -->
                            <!--Front and Back-->
                            <geom type="mesh" group="0" name="digit0_back_collision" euler="3.1416 0 1.5708" pos="0.028 0.015 0.036" material="black_resin" mesh="digit_back"  mass="0.05" contype="32" conaffinity="32" friction="1 0.05 0.01" solimp="1.1 1.2 0.001 0.5 2" solref="0.02 1"/>
                            <geom type="mesh" contype="0" conaffinity="0" group="1" name="digit0_back_visual" material="black_resin"  mesh="digit_back" mass="0.0005" euler="3.1416 0 1.5708" pos="0.028 0.015 0.036"/>
                            <!-- <geom name="digit0_adapter"  type="mesh" euler="0 -1.5708 3.1416" pos="0.05 0.0097 0.0326" material="silver" mesh="digit_adapter"  mass="0.05" contype="32" conaffinity="32" friction="1 0.05 0.01" solimp="1.1 1.2 0.001 0.5 2" solref="0.02 1"/> -->
                            <!--Glass Cover-->
                            <geom type="mesh" contype="0" conaffinity="0" group="1" name="digit0_glass_visual" material="transparent_glass"  mesh="digit_glass" mass="0.005"   pos="0.024 -0.0085 0.017" euler="0 0 1.5708"/>
                            <!--Elastomer-->
                            <geom type="mesh" contype="0" conaffinity="0" group="1" name="digit0_elastomer_visual" mesh="digit_gel" pos="0.024 -0.0085 0.032" euler="0 0 1.5708" rgba="0.9 0.95 1 0.0"/>
                            <!--Elastomer Cover-->
                            <!-- <geom name="digit0_elastCover" type="mesh" mesh="digit_gel_cover" pos="0.025 -0.01 0.031" euler="0 0 1.5708" contype="0" conaffinity="0" material="silver"
                                    friction="1 0.05 0.01" solimp="1.1 1.2 0.001 0.5 2" solref="0.02 1"/> -->
                            <geom type="mesh" contype="0" conaffinity="0" group="1" name="digit0_elastCover_visual" mesh="digit_curve" pos="0.024 -0.0083 0.0305" euler="0 0 1.5708" material="silver"
                                friction="1 0.05 0.01" solimp="1.1 1.2 0.001 0.5 2" solref="0.02 1"/>
                            <!--Gel Camera-->
                            <camera name="digit0_camera" mode="fixed" pos="0.0129 0.0014 0.008" euler="0 3.14159 1.5708" fovy="30"/>
                            <!-- <site name="digit0_pos" type="sphere" pos="0.0129 0.0014 0.008" rgba="1 0 1 1" size=".008 .008 .008"/> -->
                            <!-- Friction placeholder -->
                            <geom name="digit0_friction_collision" group="0" type="box" size="0.013 0.013 0.00001" euler="0 0 0" pos="0.012 0.001 0.0372" contype="32" conaffinity="32" rgba="0 0 1 0"
                                    friction="1 0.05 0.01" solimp="1.1 1.2 0.001 0.5 2" solref="0.02 1"/>
                        </body>
                    </body>
                    <!-- tactile -->
                </body>

            </body>
            <body name="left_inner_knuckle" pos="0 -0.0127 0.06142" quat="0 0 0 1">
                <inertial pos="0.000123012 0.0507851 0.00103969" quat="0.497203 0.502496 -0.507943 0.492221" mass="0.0271177" diaginertia="2.83809e-05 2.61936e-05 2.81319e-06" />
                <joint name="left_inner_knuckle_joint" pos="0 0 0" axis="1 0 0" limited="true" range="0 0.8757" />
                <geom type="mesh" contype="0" conaffinity="0" group="1" rgba="0.1 0.1 0.1 1" name="left_inner_knuckle_visual" mesh="robotiq_arg2f_85_inner_knuckle_vis" />
                <geom type="mesh" group="0" rgba="0.1 0.1 0.1 1" mesh="robotiq_arg2f_85_inner_knuckle" name="left_inner_knuckle_collision" />
            </body>
            <body name="right_outer_knuckle" pos="0 0.0306011 0.054904">
                <inertial pos="0.000163875 0.0554825 -0.0100755" quat="0.920541 0.390623 -0.00362953 0.00231744" mass="0.0311462" diaginertia="5.11372e-05 4.89464e-05 4.95906e-06" />
                <joint name="right_outer_knuckle_joint" pos="0 0 0" axis="1 0 0" limited="true" range="0 0.8" />
                <geom type="mesh" contype="0" conaffinity="0" group="1" rgba="0.792157 0.819608 0.933333 1" name="right_outer_knuckle_visual" mesh="robotiq_arg2f_85_outer_knuckle_vis" />
                <geom type="mesh" group="0" rgba="0.792157 0.819608 0.933333 1" mesh="robotiq_arg2f_85_outer_knuckle" name="right_outer_knuckle_collision" solref="0.01 0.25" />
                <geom pos="0 0.0315 -0.0041" type="mesh" contype="0" conaffinity="0" group="1" rgba="0.1 0.1 0.1 1" name="right_outer_finger_visual" mesh="robotiq_arg2f_85_outer_finger_vis" />
                <geom pos="0 0.0315 -0.0041" type="mesh" group="0" rgba="0.1 0.1 0.1 1" mesh="robotiq_arg2f_85_outer_finger" name="right_outer_finger_collision" solref="0.01 0.25" />
                <body name="right_inner_finger" pos="0 0.0376 0.043">
                    <inertial pos="0.000199506 0.0032692 0.00175282" quat="0.933621 0.35825 -0.00273441 0.00104851" mass="0.0156391" diaginertia="1.57977e-05 1.51089e-05 1.4647e-06" />
                    <joint name="right_inner_finger_joint" pos="0 0 0" axis="1 0 0" limited="true" range="-0.8757 0.8757" />
                    <geom type="mesh" contype="0" conaffinity="0" group="1" rgba="0.1 0.1 0.1 1" name="right_inner_finger_visual" mesh="robotiq_arg2f_85_inner_finger_vis" />
                    <geom type="mesh" group="0" rgba="0.1 0.1 0.1 1" mesh="robotiq_arg2f_85_inner_finger" name="right_inner_finger_collision" solref="0.01 0.25" />
                    <geom size="0.011 0.003175 0.01875" pos="0 -0.0220203 0.03242" type="box" contype="0" conaffinity="0" group="1" rgba="0.9 0.9 0.9 1" name="right_fingertip_visual" />
                    <geom size="0.011 0.003175 0.01875" pos="0 -0.0220203 0.03242" type="box" group="0" rgba="0.9 0.9 0.9 1" name="right_fingertip_collision" solref="0.01 0.25" />
                    <geom size="0.010 0.001 0.01675" pos="0 -0.0245203 0.03242" type="box" group="0" name="right_fingerpad_collision" />
                    <!-- tactile -->
                    <body name="digit_1" pos="-0.0025 0.01 0.08" euler="1.5708 0 -1.5708"> 
                    <!-- 左右 前后 上下 -->
                        <!-- <include file="digit1_sensor.xml"></include> -->
                        <body name="digit1_sensor" pos="0 0 0">
                            <site name="digit1_site" pos="0.012 0 0.035" rgba="1 0 0 .0" size="0.02 0.02 0.02" group="1"/>
                            <!-- <joint name="digit_joint" type="hinge" damping="0.01"></joint> -->
                            <!--Front and Back-->
                            <geom type="mesh" group="0" name="digit1_back_collision" euler="3.1416 0 1.5708" pos="0.028 0.015 0.036" material="black_resin" mesh="digit_back"  mass="0.05" contype="32" conaffinity="32" friction="1 0.05 0.01" solimp="1.1 1.2 0.001 0.5 2" solref="0.02 1"/>
                            <geom type="mesh" contype="0" conaffinity="0" group="1" name="digit1_back_visual" material="black_resin"  mesh="digit_back" mass="0.0005" euler="3.1416 0 1.5708" pos="0.028 0.015 0.036"/>
                            <!-- <geom name="digit1_adapter"  type="mesh" euler="0 -1.5708 3.1416" pos="0.05 0.0097 0.0326" material="silver" mesh="digit_adapter"  mass="0.05" contype="32" conaffinity="32" friction="1 0.05 0.01" solimp="1.1 1.2 0.001 0.5 2" solref="0.02 1"/> -->
                            <!--Glass Cover-->
                            <geom type="mesh" contype="0" conaffinity="0" group="1" name="digit1_glass_visual" material="transparent_glass"  mesh="digit_glass" mass="0.005"   pos="0.024 -0.0085 0.017" euler="0 0 1.5708"/>
                            <!--Elastomer-->
                            <geom type="mesh" contype="0" conaffinity="0" group="1" name="digit1_elastomer_visual" mesh="digit_gel" pos="0.024 -0.0085 0.032" euler="0 0 1.5708" rgba="0.9 0.95 1 0.0"/>
                            <!--Elastomer Cover-->
                            <!-- <geom name="digit0_elastCover" type="mesh" mesh="digit_gel_cover" pos="0.025 -0.01 0.031" euler="0 0 1.5708" contype="0" conaffinity="0" material="silver"
                                    friction="1 0.05 0.01" solimp="1.1 1.2 0.001 0.5 2" solref="0.02 1"/> -->
                            <geom type="mesh" contype="0" conaffinity="0" group="1" name="digit1_elastCover_visual" mesh="digit_curve" pos="0.024 -0.0083 0.0305" euler="0 0 1.5708" material="silver"
                                friction="1 0.05 0.01" solimp="1.1 1.2 0.001 0.5 2" solref="0.02 1"/>
                            <!--Gel Camera-->
                            <camera name="digit1_camera" mode="fixed" pos="0.0129 0.0014 0.008" euler="0 3.14159 1.5708" fovy="30"/>
                            <!-- <site name="digit0_pos" type="sphere" pos="0.0129 0.0014 0.008" rgba="1 0 1 1" size=".008 .008 .008"/> -->
                            <!-- Friction placeholder -->
                            <geom name="digit1_friction_collision" group="0" type="box" size="0.013 0.013 0.00001" euler="0 0 0" pos="0.012 0.001 0.0372" contype="32" conaffinity="32" rgba="0 0 1 0"
                                    friction="1 0.05 0.01" solimp="1.1 1.2 0.001 0.5 2" solref="0.02 1"/>
                        </body>
                    </body>
                    <!-- tactile -->
                </body>
            </body>
            <body name="right_inner_knuckle" pos="0 0.0127 0.06142">
                <inertial pos="0.000123012 0.0507851 0.00103969" quat="0.497203 0.502496 -0.507943 0.492221" mass="0.0271177" diaginertia="2.83809e-05 2.61936e-05 2.81319e-06" />
                <joint name="right_inner_knuckle_joint" pos="0 0 0" axis="1 0 0" limited="true" range="0 0.8757" />
                <geom type="mesh" contype="0" conaffinity="0" group="1" rgba="0.1 0.1 0.1 1" name="right_inner_knuckle_visual" mesh="robotiq_arg2f_85_inner_knuckle_vis" />
                <geom type="mesh" group="0" rgba="0.1 0.1 0.1 1" mesh="robotiq_arg2f_85_inner_knuckle" name="right_inner_knuckle_collision" />
            </body>
        </body>
    </worldbody>
    <sensor>
        <force name="force_ee" site="ft_frame"/>
        <torque name="torque_ee" site="ft_frame"/>
    </sensor>

</mujoco>
